Workbook

Sheet Ingredient Breakdown
A1: Meal | B1: Ingredient | C1: Amount | D1: Calories | E1: Protein (g) | F1: Carbs (g) | G1: Fat (g) | H1: Fiber (g) | I1: Sugar (g) | J1: Sodium (mg) | K1: Potassium (mg) | L1: Calcium (mg) | M1: Iron (mg) | N1: Notable micronutrients
A2: Breakfast - Simple | B2: 3 large eggs | C2: 3 eggs | D2: 216 | E2: 18.9 | F2: 1.2 | G2: 14.4 | H2: 0 | I2: 1.1 | J2: 213 | K2: 207 | L2: 84 | M2: 1.8 | N2: Choline 441mg, Vit D 132 IU, B12 1.35mcg, Selenium 45mcg
A3: Breakfast - Simple | B3: Avocado | C3: 1/2 medium (75g) | D3: 120 | E3: 1.5 | F3: 6 | G3: 11 | H3: 5 | I3: 0.5 | J3: 7 | K3: 360 | L3: 9 | M3: 0.4 | N3: Potassium 360mg, Folate 61mcg, Magnesium 22mg
A4: Breakfast - Simple | B4: TOTAL | D4: =SUM(D2:D3) -> 336 | E4: =SUM(E2:E3) -> 20.4 | F4: =SUM(F2:F3) -> 7.2 | G4: =SUM(G2:G3) -> 25.4 | H4: =SUM(H2:H3) -> 5 | I4: =SUM(I2:I3) -> 1.6 | J4: =SUM(J2:J3) -> 220 | K4: =SUM(K2:K3) -> 567 | ... M4: =SUM(M2:M3) -> 2.2
A6: Breakfast - Eggs & Avo (Full) | B6: 3 large eggs | C6: 3 eggs | D6: 216 | E6: 18.9 | F6: 1.2 | G6: 14.4 | H6: 0 | I6: 1.1 | J6: 213 | K6: 207 | L6: 84 | M6: 1.8 | N6: Choline 441mg, Vit D 132 IU, B12 1.35mcg
A7: Breakfast - Eggs & Avo (Full) | B7: Avocado | C7: 1/2 medium (75g) | D7: 120 | E7: 1.5 | F7: 6 | G7: 11 | H7: 5 | I7: 0.5 | J7: 7 | K7: 360 | L7: 9 | M7: 0.4 | N7: Potassium 360mg, Folate 61mcg
A8: Breakfast - Eggs & Avo (Full) | B8: Salsa | C8: 2 tbsp (30g) | D8: 10 | E8: 0.5 | F8: 2 | G8: 0 | H8: 0.5 | I8: 1.5 | J8: 200 | K8: 60 | L8: 8 | M8: 0.1 | N8: Vit C
A9: Breakfast - Eggs & Avo (Full) | B9: Sourdough | C9: 1/2 slice (25g) | D9: 55 | E9: 2 | F9: 11 | G9: 0.5 | H9: 0.5 | I9: 0.5 | J9: 110 | K9: 30 | L9: 5 | M9: 0.7 | N9: Selenium, manganese
A10: Breakfast - Eggs & Avo (Full) | B10: Coffee + Califia oat barista | C10: 12 oz + 2 oz | D10: 25 | E10: 0.5 | F10: 2 | G10: 1 | H10: 0 | I10: 1 | J10: 30 | K10: 130 | L10: 50 | M10: 0.2 | N10: Fortified calcium, Vit D
A11: Breakfast - Eggs & Avo (Full) | B11: TOTAL | D11: =SUM(D6:D10) -> 426 | E11: =SUM(E6:E10) -> 23.4 | F11: =SUM(F6:F10) -> 22.2 | G11: =SUM(G6:G10) -> 26.9 | H11: =SUM(H6:H10) -> 6 | I11: =SUM(I6:I10) -> 4.6 | J11: =SUM(J6:J10) -> 560 | K11: =SUM(K6:K10) -> 787 | ... M11: =SUM(M6:M10) -> 3.2
A13: Breakfast - High Protein | B13: 3 large eggs | C13: 3 eggs | D13: 216 | E13: 18.9 | F13: 1.2 | G13: 14.4 | H13: 0 | I13: 1.1 | J13: 213 | K13: 207 | L13: 84 | M13: 1.8 | N13: Choline 441mg, Vit D 132 IU, B12 1.35mcg
A14: Breakfast - High Protein | B14: Avocado | C14: 1/2 medium (75g) | D14: 120 | E14: 1.5 | F14: 6 | G14: 11 | H14: 5 | I14: 0.5 | J14: 7 | K14: 360 | L14: 9 | M14: 0.4 | N14: Potassium 360mg, Folate 61mcg
A15: Breakfast - High Protein | B15: Salsa | C15: 2 tbsp (30g) | D15: 10 | E15: 0.5 | F15: 2 | G15: 0 | H15: 0.5 | I15: 1.5 | J15: 200 | K15: 60 | L15: 8 | M15: 0.1 | N15: Vit C
A16: Breakfast - High Protein | B16: Sourdough | C16: 1/2 slice (25g) | D16: 55 | E16: 2 | F16: 11 | G16: 0.5 | H16: 0.5 | I16: 0.5 | J16: 110 | K16: 30 | L16: 5 | M16: 0.7 | N16: Selenium, manganese
A17: Breakfast - High Protein | B17: Coffee + Califia oat barista | C17: 12 oz + 2 oz | D17: 25 | E17: 0.5 | F17: 2 | G17: 1 | H17: 0 | I17: 1 | J17: 30 | K17: 130 | L17: 50 | M17: 0.2 | N17: Fortified calcium
A18: Breakfast - High Protein | B18: Nonfat Greek yogurt | C18: 3/4 cup (170g) | D18: 95 | E18: 16 | F18: 6 | G18: 0 | H18: 0 | I18: 5 | J18: 65 | K18: 220 | L18: 170 | M18: 0.1 | N18: B12, Calcium 170mg
A19: Breakfast - High Protein | B19: TOTAL | D19: =SUM(D13:D18) -> 521 | E19: =SUM(E13:E18) -> 39.4 | F19: =SUM(F13:F18) -> 28.2 | G19: =SUM(G13:G18) -> 26.9 | H19: =SUM(H13:H18) -> 6 | I19: =SUM(I13:I18) -> 9.6 | J19: =SUM(J13:J18) -> 625 | K19: =SUM(K13:K18) -> 1007 | ... M19: =SUM(M13:M18) -> 3.3
A21: Lunch - Chicken Power Bowl | B21: Grilled chicken breast | C21: 6 oz (170g) | D21: 280 | E21: 52 | F21: 0 | G21: 6 | H21: 0 | I21: 0 | J21: 125 | K21: 440 | L21: 12 | M21: 1 | N21: Niacin 17mg, B6 1.2mg, Selenium 40mcg
A22: Lunch - Chicken Power Bowl | B22: Mixed greens + vegetables | C22: 2 cups (150g) | D22: 40 | E22: 2 | F22: 8 | G22: 0.5 | H22: 3 | I22: 4 | J22: 30 | K22: 400 | L22: 60 | M22: 1.5 | N22: Vit C 40mg, Vit K 160mcg, Folate
A23: Lunch - Chicken Power Bowl | B23: Brown rice, cooked | C23: 1/2 cup (100g) | D23: 108 | E23: 2.5 | F23: 22 | G23: 0.9 | H23: 1.8 | I23: 0 | J23: 5 | K23: 75 | L23: 10 | M23: 0.5 | N23: Magnesium 43mg
A24: Lunch - Chicken Power Bowl | B24: Olive oil | C24: 1 tbsp (14g) | D24: 120 | E24: 0 | F24: 0 | G24: 14 | H24: 0 | I24: 0 | J24: 0 | K24: 0 | L24: 0 | M24: 0 | N24: Vit E 2mg
A25: Lunch - Chicken Power Bowl | B25: Vinegar / salsa | C25: to taste | D25: 10 | E25: 0.3 | F25: 2 | G25: 0 | H25: 0.3 | I25: 1 | J25: 100 | K25: 40 | L25: 5 | M25: 0.1 | N25: trace
A26: Lunch - Chicken Power Bowl | B26: TOTAL | D26: =SUM(D21:D25) -> 558 | E26: =SUM(E21:E25) -> 56.8 | F26: =SUM(F21:F25) -> 32 | G26: =SUM(G21:G25) -> 21.4 | H26: =SUM(H21:H25) -> 5.1 | I26: =SUM(I21:I25) -> 5 | J26: =SUM(J21:J25) -> 260 | K26: =SUM(K21:K25) -> 955 | ... M26: =SUM(M21:M25) -> 3.1
A28: Snack - Whey Shake + Apple | B28: Whey protein | C28: 1 scoop (32g) | D28: 120 | E28: 25 | F28: 3 | G28: 1.5 | H28: 0 | I28: 2 | J28: 60 | K28: 160 | L28: 150 | M28: 0.3 | N28: Calcium, leucine
A29: Snack - Whey Shake + Apple | B29: Apple | C29: 1 medium (182g) | D29: 95 | E29: 0.5 | F29: 25 | G29: 0.3 | H29: 4 | I29: 19 | J29: 2 | K29: 195 | L29: 11 | M29: 0.2 | N29: Vit C 8mg
A30: Snack - Whey Shake + Apple | B30: TOTAL | D30: =SUM(D28:D29) -> 215 | E30: =SUM(E28:E29) -> 25.5 | F30: =SUM(F28:F29) -> 28 | G30: =SUM(G28:G29) -> 1.8 | H30: =SUM(H28:H29) -> 4 | I30: =SUM(I28:I29) -> 21 | J30: =SUM(J28:J29) -> 62 | K30: =SUM(K28:K29) -> 355 | ... M30: =SUM(M28:M29) -> 0.5
A32: Snack - Cottage Cheese + Berries | B32: Lowfat cottage cheese | C32: 1 cup (226g) | D32: 180 | E32: 24 | F32: 8 | G32: 5 | H32: 0 | I32: 7 | J32: 700 | K32: 200 | L32: 140 | M32: 0.1 | N32: B12, Selenium (high sodium)
A33: Snack - Cottage Cheese + Berries | B33: Mixed berries | C33: 1/2 cup (75g) | D33: 35 | E33: 0.5 | F33: 9 | G33: 0.3 | H33: 2 | I33: 6 | J33: 1 | K33: 75 | L33: 10 | M33: 0.3 | N33: Vit C 25mg
A34: Snack - Cottage Cheese + Berries | B34: TOTAL | D34: =SUM(D32:D33) -> 215 | E34: =SUM(E32:E33) -> 24.5 | F34: =SUM(F32:F33) -> 17 | G34: =SUM(G32:G33) -> 5.3 | H34: =SUM(H32:H33) -> 2 | I34: =SUM(I32:I33) -> 13 | J34: =SUM(J32:J33) -> 701 | K34: =SUM(K32:K33) -> 275 | ... M34: =SUM(M32:M33) -> 0.4
A36: Dinner - Sirloin + Potatoes + Veg | B36: Lean sirloin, cooked | C36: 7 oz (198g) | D36: 380 | E36: 55 | F36: 0 | G36: 16 | H36: 0 | I36: 0 | J36: 110 | K36: 530 | L36: 20 | M36: 3.5 | N36: Zinc 9mg, B12, Niacin, Selenium
A37: Dinner - Sirloin + Potatoes + Veg | B37: Potatoes, boiled | C37: 1 cup (150g) | D37: 130 | E37: 3 | F37: 30 | G37: 0.2 | H37: 3 | I37: 1.5 | J37: 10 | K37: 515 | L37: 15 | M37: 1.1 | N37: Vit C, B6
A38: Dinner - Sirloin + Potatoes + Veg | B38: Roasted vegetables + 1 tsp oil | C38: 1.5 cups (150g) | D38: 90 | E38: 4 | F38: 10 | G38: 5 | H38: 4 | I38: 3 | J38: 30 | K38: 300 | L38: 60 | M38: 1 | N38: Vit C 80mg, Vit K
A39: Dinner - Sirloin + Potatoes + Veg | B39: TOTAL | D39: =SUM(D36:D38) -> 600 | E39: =SUM(E36:E38) -> 62 | F39: =SUM(F36:F38) -> 40 | G39: =SUM(G36:G38) -> 21.2 | H39: =SUM(H36:H38) -> 7 | I39: =SUM(I36:I38) -> 4.5 | J39: =SUM(J36:J38) -> 150 | K39: =SUM(K36:K38) -> 1345 | ... M39: =SUM(M36:M38) -> 5.6
A41: Dinner - Salmon + Rice + Veg | B41: Salmon, cooked | C41: 6 oz (170g) | D41: 350 | E41: 40 | F41: 0 | G41: 20 | H41: 0 | I41: 0 | J41: 100 | K41: 700 | L41: 18 | M41: 0.8 | N41: Omega-3 3.5g, Vit D 570 IU, B12 5mcg
A42: Dinner - Salmon + Rice + Veg | B42: Brown rice, cooked | C42: 3/4 cup (140g) | D42: 160 | E42: 3.5 | F42: 33 | G42: 1.3 | H42: 2.5 | I42: 0 | J42: 8 | K42: 110 | L42: 15 | M42: 0.7 | N42: Magnesium 60mg
A43: Dinner - Salmon + Rice + Veg | B43: Roasted vegetables + 1 tsp oil | C43: 1.5 cups (150g) | D43: 90 | E43: 4 | F43: 10 | G43: 5 | H43: 4 | I43: 3 | J43: 30 | K43: 300 | L43: 60 | M43: 1 | N43: Vit C, Vit K
A44: Dinner - Salmon + Rice + Veg | B44: TOTAL | D44: =SUM(D41:D43) -> 600 | E44: =SUM(E41:E43) -> 47.5 | F44: =SUM(F41:F43) -> 43 | G44: =SUM(G41:G43) -> 26.3 | H44: =SUM(H41:H43) -> 6.5 | I44: =SUM(I41:I43) -> 3 | J44: =SUM(J41:J43) -> 138 | K44: =SUM(K41:K43) -> 1110 | ... M44: =SUM(M41:M43) -> 2.5
A46: Baja Salad + Grilled Chicken | B46: Grilled chicken | C46: 6 oz (170g) | D46: 280 | E46: 52 | F46: 0 | G46: 6 | H46: 0 | I46: 0 | J46: 125 | K46: 440 | L46: 12 | M46: 1 | N46: Niacin, B6, Selenium
A47: Baja Salad + Grilled Chicken | B47: Romaine + mixed veg | C47: 2 cups (150g) | D47: 30 | E47: 2 | F47: 6 | G47: 0.3 | H47: 3 | I47: 3 | J47: 25 | K47: 350 | L47: 50 | M47: 1.2 | N47: Vit A, Vit C, Vit K
A48: Baja Salad + Grilled Chicken | B48: Black beans | C48: 1/4 cup (45g) | D48: 55 | E48: 3.5 | F48: 10 | G48: 0.2 | H48: 4 | I48: 0 | J48: 95 | K48: 170 | L48: 15 | M48: 0.9 | N48: Folate, Magnesium
...

Sheet Preset Meals
A1: Preset Meals - Quick Add to Tracker
A3: Meal | B3: Calories | C3: Protein (g) | D3: Carbs (g) | E3: Fat (g) | F3: Fiber (g) | G3: Sugar (g) | H3: Sodium (mg) | I3: Potassium (mg) | J3: Calcium (mg) | K3: Iron (mg) | L3: Notable micronutrients
A4: Breakfast - Simple | B4: ='Ingredient Breakdown'!D4 -> 336 | C4: ='Ingredient Breakdown'!E4 -> 20.4 | D4: ='Ingredient Breakdown'!F4 -> 7.2 | E4: ='Ingredient Breakdown'!G4 -> 25.4 | F4: ='Ingredient Breakdown'!H4 -> 5 | G4: ='Ingredient Breakdown'!I4 -> 1.6 | H4: ='Ingredient Breakdown'!J4 -> 220 | I4: ='Ingredient Breakdown'!K4 -> 567 | ... K4: ='Ingredient Breakdown'!M4 -> 2.2 | L4: Choline, Vit D, B12, Folate, Potassium
A5: Breakfast - Eggs & Avo (Full) | B5: ='Ingredient Breakdown'!D11 -> 426 | C5: ='Ingredient Breakdown'!E11 -> 23.4 | D5: ='Ingredient Breakdown'!F11 -> 22.2 | E5: ='Ingredient Breakdown'!G11 -> 26.9 | F5: ='Ingredient Breakdown'!H11 -> 6 | G5: ='Ingredient Breakdown'!I11 -> 4.6 | H5: ='Ingredient Breakdown'!J11 -> 560 | I5: ='Ingredient Breakdown'!K11 -> 787 | ... K5: ='Ingredient Breakdown'!M11 -> 3.2 | L5: Choline, Vit D, B12, Folate, Potassium
A6: Breakfast - High Protein | B6: ='Ingredient Breakdown'!D19 -> 521 | C6: ='Ingredient Breakdown'!E19 -> 39.4 | D6: ='Ingredient Breakdown'!F19 -> 28.2 | E6: ='Ingredient Breakdown'!G19 -> 26.9 | F6: ='Ingredient Breakdown'!H19 -> 6 | G6: ='Ingredient Breakdown'!I19 -> 9.6 | H6: ='Ingredient Breakdown'!J19 -> 625 | I6: ='Ingredient Breakdown'!K19 -> 1007 | ... K6: ='Ingredient Breakdown'!M19 -> 3.3 | L6: Choline, B12, Calcium, Folate, Potassium
A7: Lunch - Chicken Power Bowl | B7: ='Ingredient Breakdown'!D26 -> 558 | C7: ='Ingredient Breakdown'!E26 -> 56.8 | D7: ='Ingredient Breakdown'!F26 -> 32 | E7: ='Ingredient Breakdown'!G26 -> 21.4 | F7: ='Ingredient Breakdown'!H26 -> 5.1 | G7: ='Ingredient Breakdown'!I26 -> 5 | H7: ='Ingredient Breakdown'!J26 -> 260 | I7: ='Ingredient Breakdown'!K26 -> 955 | ... K7: ='Ingredient Breakdown'!M26 -> 3.1 | L7: Niacin, B6, Vit C, Vit K, Folate, Selenium
A8: Snack - Whey Shake + Apple | B8: ='Ingredient Breakdown'!D30 -> 215 | C8: ='Ingredient Breakdown'!E30 -> 25.5 | D8: ='Ingredient Breakdown'!F30 -> 28 | E8: ='Ingredient Breakdown'!G30 -> 1.8 | F8: ='Ingredient Breakdown'!H30 -> 4 | G8: ='Ingredient Breakdown'!I30 -> 21 | H8: ='Ingredient Breakdown'!J30 -> 62 | I8: ='Ingredient Breakdown'!K30 -> 355 | ... K8: ='Ingredient Breakdown'!M30 -> 0.5 | L8: Calcium, Vit C, leucine
A9: Snack - Cottage Cheese + Berries | B9: ='Ingredient Breakdown'!D34 -> 215 | C9: ='Ingredient Breakdown'!E34 -> 24.5 | D9: ='Ingredient Breakdown'!F34 -> 17 | E9: ='Ingredient Breakdown'!G34 -> 5.3 | F9: ='Ingredient Breakdown'!H34 -> 2 | G9: ='Ingredient Breakdown'!I34 -> 13 | H9: ='Ingredient Breakdown'!J34 -> 701 | I9: ='Ingredient Breakdown'!K34 -> 275 | ... K9: ='Ingredient Breakdown'!M34 -> 0.4 | L9: B12, Calcium, Vit C, Selenium
A10: Dinner - Sirloin + Potatoes + Veg | B10: ='Ingredient Breakdown'!D39 -> 600 | C10: ='Ingredient Breakdown'!E39 -> 62 | D10: ='Ingredient Breakdown'!F39 -> 40 | E10: ='Ingredient Breakdown'!G39 -> 21.2 | F10: ='Ingredient Breakdown'!H39 -> 7 | G10: ='Ingredient Breakdown'!I39 -> 4.5 | H10: ='Ingredient Breakdown'!J39 -> 150 | I10: ='Ingredient Breakdown'!K39 -> 1345 | ... K10: ='Ingredient Breakdown'!M39 -> 5.6 | L10: Iron, Zinc, B12, Niacin, Vit C, Potassium
A11: Dinner - Salmon + Rice + Veg | B11: ='Ingredient Breakdown'!D44 -> 600 | C11: ='Ingredient Breakdown'!E44 -> 47.5 | D11: ='Ingredient Breakdown'!F44 -> 43 | E11: ='Ingredient Breakdown'!G44 -> 26.3 | F11: ='Ingredient Breakdown'!H44 -> 6.5 | G11: ='Ingredient Breakdown'!I44 -> 3 | H11: ='Ingredient Breakdown'!J44 -> 138 | I11: ='Ingredient Breakdown'!K44 -> 1110 | ... K11: ='Ingredient Breakdown'!M44 -> 2.5 | L11: Omega-3, Vit D, B12, Magnesium, Selenium
A12: Baja Salad + Grilled Chicken | B12: ='Ingredient Breakdown'!D53 -> 590 | C12: ='Ingredient Breakdown'!E53 -> 59.55 | D12: ='Ingredient Breakdown'!F53 -> 31 | E12: ='Ingredient Breakdown'!G53 -> 25.5 | F12: ='Ingredient Breakdown'!H53 -> 11 | G12: ='Ingredient Breakdown'!I53 -> 7.3 | H12: ='Ingredient Breakdown'!J53 -> 604 | I12: ='Ingredient Breakdown'!K53 -> 1270 | ... K12: ='Ingredient Breakdown'!M53 -> 3.7 | L12: Niacin, Folate, Vit C, Potassium, fiber
A13: Chicken Kabobs + Veggies (home) | B13: ='Ingredient Breakdown'!D58 -> 515 | C13: ='Ingredient Breakdown'!E58 -> 64 | D13: ='Ingredient Breakdown'!F58 -> 14 | E13: ='Ingredient Breakdown'!G58 -> 21.5 | F13: ='Ingredient Breakdown'!H58 -> 4 | G13: ='Ingredient Breakdown'!I58 -> 8 | H13: ='Ingredient Breakdown'!J58 -> 160 | I13: ='Ingredient Breakdown'!K58 -> 1000 | ... K13: ='Ingredient Breakdown'!M58 -> 2.1 | L13: Niacin, B6, Vit C, Vit A, Potassium
A14: Hamburger Bowl (home) | B14: ='Ingredient Breakdown'!D64 -> 485 | C14: ='Ingredient Breakdown'!E64 -> 55 | D14: ='Ingredient Breakdown'!F64 -> 9.5 | E14: ='Ingredient Breakdown'!G64 -> 26.2 | F14: ='Ingredient Breakdown'!H64 -> 2 | G14: ='Ingredient Breakdown'!I64 -> 6 | H14: ='Ingredient Breakdown'!J64 -> 600 | I14: ='Ingredient Breakdown'!K64 -> 758 | ... K14: ='Ingredient Breakdown'!M64 -> 3.9 | L14: Iron, Zinc, B12, Calcium, Niacin
A15: Ground Chicken Mexican Bowl (home) | B15: ='Ingredient Breakdown'!D72 -> 583 | C15: ='Ingredient Breakdown'!E72 -> 57.25 | D15: ='Ingredient Breakdown'!F72 -> 43.5 | E15: ='Ingredient Breakdown'!G72 -> 22.3 | F15: ='Ingredient Breakdown'!H72 -> 10.3 | G15: ='Ingredient Breakdown'!I72 -> 3.3 | H15: ='Ingredient Breakdown'!J72 -> 644 | I15: ='Ingredient Breakdown'!K72 -> 1090 | ... K15: ='Ingredient Breakdown'!M72 -> 3.5 | L15: Niacin, B6, Folate, Vit C, fiber

Sheet Eating Out + More Meals
A1: Dinner Out (3 options each) + More Meals
A3: Meal | B3: Order / Build | C3: Calories | D3: Protein (g) | E3: Carbs (g) | F3: Fat (g) | G3: Fiber (g) | H3: Sodium (mg) | I3: Notes
A4: CHA CHA'S LATIN KITCHEN
A5: Chicken or Steak Fajitas | B5: Grilled achiote chicken or skirt steak + fajita peppers & onions, 1-2 corn tortillas, pico + guac. Skip rice, beans, chips. | C5: 600 | D5: 50 | E5: 30 | F5: 28 | G5: 5 | H5: 900 | I5: Your go-to. Full plate with all sides runs 1000+; build it protein + veggies.
A6: Carne Asada | B6: Grilled skirt steak, achiote onions, poblano peppers, chimichurri. Limit or skip the potatoes. | C6: 550 | D6: 48 | E6: 18 | F6: 30 | G6: 4 | H6: 800 | I6: Clean steak + peppers. Chimichurri is fine, it's herb + oil.
A7: Roasted Yucatan Chicken | B7: Yucatan-spiced roasted chicken, calabasitas (squash), salsa, 1-2 corn tortillas. | C7: 520 | D7: 50 | E7: 22 | F7: 22 | G7: 5 | H7: 700 | I7: Leanest of the three. Grilled salmon or chopped salad w/ chicken also great.
A8: BAJA FISH TACOS
A9: Charbroiled Wahoo Salad | B9: Charbroiled (grilled) wahoo on the house salad, dressing on side, light cheese. | C9: 450 | D9: 40 | E9: 20 | F9: 22 | G9: 5 | H9: 650 | I9: Never beer-battered 'Ensenada'. Charbroiled or blackened only.
A10: Charbroiled Fish Tacos x3 | B10: 3 charbroiled wahoo tacos on corn, cabbage, salsa, light or no Baja sauce. | C10: 480 | D10: 38 | E10: 42 | F10: 16 | G10: 6 | H10: 750 | I10: Corn tortillas, not flour. Skip the rice + beans combo.
A11: Wahoo Ceviche | B11: Lime-cured wahoo, pico, avocado. Eat over lettuce or with a few chips. | C11: 350 | D11: 35 | E11: 18 | F11: 14 | G11: 4 | H11: 600 | I11: Lightest, leanest, high protein.
A12: QUE VIDA (Yorba Linda)
A13: Wood-Fire Salmon Salad | B13: Grilled salmon, kale, squash, roasted corn, avocado, mint citrus vinaigrette. Dressing on side. | C13: 520 | D13: 40 | E13: 22 | F13: 28 | G13: 6 | H13: 600 | I13: Skip tortilla strips.
A14: Grilled Chicken/Shrimp Salad | B14: Grilled shrimp (or sub chicken) salad, romaine, avocado, corn, cilantro-lime dressing on side. | C14: 450 | D14: 42 | E14: 18 | F14: 22 | G14: 5 | H14: 600 | I14: Dressing on side, skip strips.
A15: Lean Protein Bowl | B15: Double grilled chicken, extra fajita veggies, skip rice + chips, light chipotle crema. | C15: 520 | D15: 55 | E15: 25 | F15: 20 | G15: 5 | H15: 800 | I15: Build it lean; grilled protein only, no beer-battered.
A16: MENDOCINO FARMS
A17: Avocado & Quinoa Ensalada + Chicken | B17: Superfood ensalada w/ grilled chicken, dressing on side (use ~half). | C17: 600 | D17: 39 | E17: 40 | F17: 35 | G17: 9 | H17: 700 | I17: Full = ~800 cal. Dressing is the lever. Big enough to split.
A18: Lemon Chicken & Farro Soup + Side Salad | B18: Cup/bowl of lemon chicken farro soup plus a side salad. | C18: 400 | D18: 28 | E18: 35 | F18: 14 | G18: 4 | H18: 900 | I18: Lightest day option. Bread on the side or skip.
A19: Greens Salad + Grilled Chicken | B19: Modern Caesar (or any greens salad) + added grilled chicken, dressing on side. | C19: 500 | D19: 38 | E19: 18 | F19: 30 | G19: 5 | H19: 800 | I19: Dressing on side is the key move here.
A20: IN-N-OUT
A21: Double-Double Protein Style | B21: No bun (lettuce wrap), no spread, no fries. | C21: 410 | D21: 30 | E21: 11 | F21: 28 | G21: 2 | H21: 1150 | I21: Order 'no spread' to trim more. Always skip fries + shake.
A22: 3x3 Protein Style | B22: Triple patty/cheese, no bun, no spread. For higher protein. | C22: 580 | D22: 45 | E22: 13 | F22: 40 | G22: 2 | H22: 1500 | I22: Most protein, but highest sodium. Occasional pick.
A23: Double Meat Protein Style (no cheese) | B23: Two patties, no cheese, no bun, no spread. Leanest build. | C23: 350 | D23: 32 | E23: 8 | F23: 24 | G23: 2 | H23: 700 | I23: Drops the cheese fat + sodium. Cleanest In-N-Out option.
A24: 5 MORE GO-TO MEALS (home, easy, high protein)
A25: Greek Yogurt Protein Bowl | B25: 1.5 cup nonfat Greek yogurt, 1/2 cup berries, 1 tbsp honey, 2 tbsp nuts/granola. | C25: 360 | D25: 36 | E25: 35 | F25: 8 | G25: 4 | H25: 110 | I25: Breakfast, snack, or light dinner.
A26: Turkey Taco Lettuce Wraps | B26: 6 oz lean ground turkey, taco seasoning, lettuce cups, salsa, 1/4 avocado, light cheese. | C26: 450 | D26: 48 | E26: 12 | F26: 22 | G26: 5 | H26: 600 | I26: Swap turkey for lean beef or chicken.
A27: Shrimp & Veggie Stir-Fry | B27: 8 oz shrimp, 2 cups mixed veg, 1/2 cup rice, light teriyaki or low-sodium soy. | C27: 450 | D27: 48 | E27: 40 | F27: 8 | G27: 5 | H27: 800 | I27: Cauliflower rice to cut carbs.
A28: Sheet-Pan Chicken + Veg + Potato | B28: 7 oz chicken, 1.5 cups veg, 1 small potato, 1 tsp oil. | C28: 520 | D28: 58 | E28: 35 | F28: 14 | G28: 7 | H28: 350 | I28: The lazy default. One pan.
A29: Seared Salmon or Tuna over Greens | B29: 6 oz salmon (or 2 cans tuna), big greens, 1 tbsp olive oil + lemon. | C29: 420 | D29: 44 | E29: 8 | F29: 24 | G29: 4 | H29: 400 | I29: Omega-3 rich. Add 1/2 cup beans on training days.
A30: NIGHTTIME
A31: Whey Shake + Moon Brew | B31: 1 scoop whey + water or almond milk; Moon Brew. | C31: 140 | D31: 25 | E31: 5 | F31: 2 | G31: 1 | H31: 80 | I31: Moon Brew ~10 cal. Hits protein before bed.

Sheet Targets & Sample Day
A1: Daily Targets
A3: Metric | B3: Target
A4: Calories | B4: 2,050 - 2,150
A5: Protein | B5: 175 - 190 g
A6: Carbs | B6: ~120 - 160 g (flexible)
A7: Fat | B7: 60 - 80 g
A8: Fiber | B8: 25 g or more
A9: Water | B9: 3 - 4 liters
A11: Sample Day (hits the targets)
A12: Meal | B12: Calories | C12: Protein (g) | D12: Carbs (g) | E12: Fat (g) | F12: Fiber (g) | G12: Sodium (mg)
A13: Breakfast - High Protein | B13: ='Preset Meals'!B6 -> 521 | C13: ='Preset Meals'!C6 -> 39.4 | D13: ='Preset Meals'!D6 -> 28.2 | E13: ='Preset Meals'!E6 -> 26.9 | F13: ='Preset Meals'!F6 -> 6 | G13: ='Preset Meals'!H6 -> 625
A14: Lunch - Chicken Power Bowl | B14: ='Preset Meals'!B7 -> 558 | C14: ='Preset Meals'!C7 -> 56.8 | D14: ='Preset Meals'!D7 -> 32 | E14: ='Preset Meals'!E7 -> 21.4 | F14: ='Preset Meals'!F7 -> 5.1 | G14: ='Preset Meals'!H7 -> 260
A15: Snack - Whey Shake + Apple | B15: ='Preset Meals'!B8 -> 215 | C15: ='Preset Meals'!C8 -> 25.5 | D15: ='Preset Meals'!D8 -> 28 | E15: ='Preset Meals'!E8 -> 1.8 | F15: ='Preset Meals'!F8 -> 4 | G15: ='Preset Meals'!H8 -> 62
A16: Dinner - Sirloin + Potatoes + Veg | B16: ='Preset Meals'!B10 -> 600 | C16: ='Preset Meals'!C10 -> 62 | D16: ='Preset Meals'!D10 -> 40 | E16: ='Preset Meals'!E10 -> 21.2 | F16: ='Preset Meals'!F10 -> 7 | G16: ='Preset Meals'!H10 -> 150
A17: Daily treat (1 cookie / square chocolate) | B17: 125 | C17: 1 | D17: 18 | E17: 5 | F17: 0 | G17: 40
A18: DAY TOTAL | B18: =SUM(B13:B17) -> 2019 | C18: =SUM(C13:C17) -> 184.7 | D18: =SUM(D13:D17) -> 146.2 | E18: =SUM(E13:E17) -> 76.3 | F18: =SUM(F13:F17) -> 22.1 | G18: =SUM(G13:G17) -> 1137
A20: Notes
A21: Restaurant numbers are meal-level estimates from published menus and nutrition data; actual values vary by location and build.
A22: Order rule for ANY restaurant: grilled/charbroiled not fried/battered, protein first, dressing/crema/cheese on the side, limit rice/tortillas/chips, salsa + veggies free.
A23: Home-meal macros are reliable; micronutrient values approximate.
A24: Ingredient Breakdown totals update automatically when you change an amount.
